[2024-10-26T19:18:14.613+0000] {local_task_job_runner.py:123} INFO - ::group::Pre task execution logs
[2024-10-26T19:18:14.631+0000] {taskinstance.py:2612} INFO - Dependencies all met for dep_context=non-requeueable deps ti=<TaskInstance: fetch_and_store_amazon_books.insert_book_data manual__2024-10-26T19:10:05.195857+00:00 [queued]>
[2024-10-26T19:18:14.639+0000] {taskinstance.py:2612} INFO - Dependencies all met for dep_context=requeueable deps ti=<TaskInstance: fetch_and_store_amazon_books.insert_book_data manual__2024-10-26T19:10:05.195857+00:00 [queued]>
[2024-10-26T19:18:14.640+0000] {taskinstance.py:2865} INFO - Starting attempt 1 of 2
[2024-10-26T19:18:14.652+0000] {taskinstance.py:2888} INFO - Executing <Task(PythonOperator): insert_book_data> on 2024-10-26 19:10:05.195857+00:00
[2024-10-26T19:18:14.660+0000] {warnings.py:112} WARNING - /home/***/.local/lib/python3.12/site-packages/***/task/task_runner/standard_task_runner.py:70: DeprecationWarning: This process (pid=471) is multi-threaded, use of fork() may lead to deadlocks in the child.
  pid = os.fork()

[2024-10-26T19:18:14.662+0000] {standard_task_runner.py:72} INFO - Started process 473 to run task
[2024-10-26T19:18:14.662+0000] {standard_task_runner.py:104} INFO - Running: ['***', 'tasks', 'run', 'fetch_and_store_amazon_books', 'insert_book_data', 'manual__2024-10-26T19:10:05.195857+00:00', '--job-id', '19', '--raw', '--subdir', 'DAGS_FOLDER/dag.py', '--cfg-path', '/tmp/tmpj5rdff3l']
[2024-10-26T19:18:14.663+0000] {standard_task_runner.py:105} INFO - Job 19: Subtask insert_book_data
[2024-10-26T19:18:14.708+0000] {task_command.py:467} INFO - Running <TaskInstance: fetch_and_store_amazon_books.insert_book_data manual__2024-10-26T19:10:05.195857+00:00 [running]> on host f1b284c02f67
[2024-10-26T19:18:14.782+0000] {taskinstance.py:3131} INFO - Exporting env vars: AIRFLOW_CTX_DAG_OWNER='***' AIRFLOW_CTX_DAG_ID='fetch_and_store_amazon_books' AIRFLOW_CTX_TASK_ID='insert_book_data' AIRFLOW_CTX_EXECUTION_DATE='2024-10-26T19:10:05.195857+00:00' AIRFLOW_CTX_TRY_NUMBER='1' AIRFLOW_CTX_DAG_RUN_ID='manual__2024-10-26T19:10:05.195857+00:00'
[2024-10-26T19:18:14.784+0000] {logging_mixin.py:190} INFO - Task instance is in running state
[2024-10-26T19:18:14.785+0000] {logging_mixin.py:190} INFO -  Previous state of the Task instance: queued
[2024-10-26T19:18:14.785+0000] {logging_mixin.py:190} INFO - Current task name:insert_book_data state:running start_date:2024-10-26 19:18:14.632195+00:00
[2024-10-26T19:18:14.786+0000] {logging_mixin.py:190} INFO - Dag name:fetch_and_store_amazon_books and current dag run status:running
[2024-10-26T19:18:14.786+0000] {taskinstance.py:731} INFO - ::endgroup::
[2024-10-26T19:18:14.795+0000] {taskinstance.py:3310} ERROR - Task failed with exception
Traceback (most recent call last):
  File "/home/airflow/.local/lib/python3.12/site-packages/airflow/models/taskinstance.py", line 767, in _execute_task
    result = _execute_callable(context=context, **execute_callable_kwargs)
             ^^^^^^^^^^^^^^^^^^^^^^^^^^^^^^^^^^^^^^^^^^^^^^^^^^^^^^^^^^^^^
  File "/home/airflow/.local/lib/python3.12/site-packages/airflow/models/taskinstance.py", line 733, in _execute_callable
    return ExecutionCallableRunner(
           ^^^^^^^^^^^^^^^^^^^^^^^^
  File "/home/airflow/.local/lib/python3.12/site-packages/airflow/utils/operator_helpers.py", line 252, in run
    return self.func(*args, **kwargs)
           ^^^^^^^^^^^^^^^^^^^^^^^^^^
  File "/home/airflow/.local/lib/python3.12/site-packages/airflow/models/baseoperator.py", line 406, in wrapper
    return func(self, *args, **kwargs)
           ^^^^^^^^^^^^^^^^^^^^^^^^^^^
  File "/home/airflow/.local/lib/python3.12/site-packages/airflow/operators/python.py", line 238, in execute
    return_value = self.execute_callable()
                   ^^^^^^^^^^^^^^^^^^^^^^^
  File "/home/airflow/.local/lib/python3.12/site-packages/airflow/operators/python.py", line 256, in execute_callable
    return runner.run(*self.op_args, **self.op_kwargs)
           ^^^^^^^^^^^^^^^^^^^^^^^^^^^^^^^^^^^^^^^^^^^
  File "/home/airflow/.local/lib/python3.12/site-packages/airflow/utils/operator_helpers.py", line 252, in run
    return self.func(*args, **kwargs)
           ^^^^^^^^^^^^^^^^^^^^^^^^^^
  File "/opt/airflow/dags/dag.py", line 92, in insert_book_data_into_postgres
    raise ValueError("No book data found")
ValueError: No book data found
[2024-10-26T19:18:14.811+0000] {logging_mixin.py:190} INFO - Task instance in failure state
[2024-10-26T19:18:14.812+0000] {logging_mixin.py:190} INFO - Task start:2024-10-26 19:18:14.632195+00:00 end:2024-10-26 19:18:14.811285+00:00 duration:0.17909
[2024-10-26T19:18:14.813+0000] {logging_mixin.py:190} INFO - Task:<Task(PythonOperator): insert_book_data> dag:<DAG: fetch_and_store_amazon_books> dagrun:<DagRun fetch_and_store_amazon_books @ 2024-10-26 19:10:05.195857+00:00: manual__2024-10-26T19:10:05.195857+00:00, state:running, queued_at: 2024-10-26 19:10:05.217993+00:00. externally triggered: True>
[2024-10-26T19:18:14.813+0000] {logging_mixin.py:190} INFO - Failure caused by No book data found
[2024-10-26T19:18:14.814+0000] {taskinstance.py:1225} INFO - Marking task as UP_FOR_RETRY. dag_id=fetch_and_store_amazon_books, task_id=insert_book_data, run_id=manual__2024-10-26T19:10:05.195857+00:00, execution_date=20241026T191005, start_date=20241026T191814, end_date=20241026T191814
[2024-10-26T19:18:14.827+0000] {taskinstance.py:340} INFO - ::group::Post task execution logs
[2024-10-26T19:18:14.828+0000] {standard_task_runner.py:124} ERROR - Failed to execute job 19 for task insert_book_data (No book data found; 473)
Traceback (most recent call last):
  File "/home/airflow/.local/lib/python3.12/site-packages/airflow/task/task_runner/standard_task_runner.py", line 117, in _start_by_fork
    ret = args.func(args, dag=self.dag)
          ^^^^^^^^^^^^^^^^^^^^^^^^^^^^^
  File "/home/airflow/.local/lib/python3.12/site-packages/airflow/cli/cli_config.py", line 49, in command
    return func(*args, **kwargs)
           ^^^^^^^^^^^^^^^^^^^^^
  File "/home/airflow/.local/lib/python3.12/site-packages/airflow/utils/cli.py", line 115, in wrapper
    return f(*args, **kwargs)
           ^^^^^^^^^^^^^^^^^^
  File "/home/airflow/.local/lib/python3.12/site-packages/airflow/cli/commands/task_command.py", line 483, in task_run
    task_return_code = _run_task_by_selected_method(args, _dag, ti)
                       ^^^^^^^^^^^^^^^^^^^^^^^^^^^^^^^^^^^^^^^^^^^^
  File "/home/airflow/.local/lib/python3.12/site-packages/airflow/cli/commands/task_command.py", line 256, in _run_task_by_selected_method
    return _run_raw_task(args, ti)
           ^^^^^^^^^^^^^^^^^^^^^^^
  File "/home/airflow/.local/lib/python3.12/site-packages/airflow/cli/commands/task_command.py", line 341, in _run_raw_task
    return ti._run_raw_task(
           ^^^^^^^^^^^^^^^^^
  File "/home/airflow/.local/lib/python3.12/site-packages/airflow/utils/session.py", line 97, in wrapper
    return func(*args, session=session, **kwargs)
           ^^^^^^^^^^^^^^^^^^^^^^^^^^^^^^^^^^^^^^
  File "/home/airflow/.local/lib/python3.12/site-packages/airflow/models/taskinstance.py", line 3004, in _run_raw_task
    return _run_raw_task(
           ^^^^^^^^^^^^^^
  File "/home/airflow/.local/lib/python3.12/site-packages/airflow/models/taskinstance.py", line 273, in _run_raw_task
    TaskInstance._execute_task_with_callbacks(
  File "/home/airflow/.local/lib/python3.12/site-packages/airflow/models/taskinstance.py", line 3158, in _execute_task_with_callbacks
    result = self._execute_task(context, task_orig)
             ^^^^^^^^^^^^^^^^^^^^^^^^^^^^^^^^^^^^^^
  File "/home/airflow/.local/lib/python3.12/site-packages/airflow/models/taskinstance.py", line 3182, in _execute_task
    return _execute_task(self, context, task_orig)
           ^^^^^^^^^^^^^^^^^^^^^^^^^^^^^^^^^^^^^^^
  File "/home/airflow/.local/lib/python3.12/site-packages/airflow/models/taskinstance.py", line 767, in _execute_task
    result = _execute_callable(context=context, **execute_callable_kwargs)
             ^^^^^^^^^^^^^^^^^^^^^^^^^^^^^^^^^^^^^^^^^^^^^^^^^^^^^^^^^^^^^
  File "/home/airflow/.local/lib/python3.12/site-packages/airflow/models/taskinstance.py", line 733, in _execute_callable
    return ExecutionCallableRunner(
           ^^^^^^^^^^^^^^^^^^^^^^^^
  File "/home/airflow/.local/lib/python3.12/site-packages/airflow/utils/operator_helpers.py", line 252, in run
    return self.func(*args, **kwargs)
           ^^^^^^^^^^^^^^^^^^^^^^^^^^
  File "/home/airflow/.local/lib/python3.12/site-packages/airflow/models/baseoperator.py", line 406, in wrapper
    return func(self, *args, **kwargs)
           ^^^^^^^^^^^^^^^^^^^^^^^^^^^
  File "/home/airflow/.local/lib/python3.12/site-packages/airflow/operators/python.py", line 238, in execute
    return_value = self.execute_callable()
                   ^^^^^^^^^^^^^^^^^^^^^^^
  File "/home/airflow/.local/lib/python3.12/site-packages/airflow/operators/python.py", line 256, in execute_callable
    return runner.run(*self.op_args, **self.op_kwargs)
           ^^^^^^^^^^^^^^^^^^^^^^^^^^^^^^^^^^^^^^^^^^^
  File "/home/airflow/.local/lib/python3.12/site-packages/airflow/utils/operator_helpers.py", line 252, in run
    return self.func(*args, **kwargs)
           ^^^^^^^^^^^^^^^^^^^^^^^^^^
  File "/opt/airflow/dags/dag.py", line 92, in insert_book_data_into_postgres
    raise ValueError("No book data found")
ValueError: No book data found
[2024-10-26T19:18:14.877+0000] {local_task_job_runner.py:266} INFO - Task exited with return code 1
[2024-10-26T19:18:14.892+0000] {taskinstance.py:3900} INFO - 0 downstream tasks scheduled from follow-on schedule check
[2024-10-26T19:18:14.894+0000] {local_task_job_runner.py:245} INFO - ::endgroup::
